<?xml version="1.0" ?>
<robot name="SomeRobot2" xmlns:xacro="http://www.ros.org/wiki/xacro">

<xacro:include filename="$(find SomeRobot2_description)/urdf/materials.xacro" />
<xacro:include filename="$(find SomeRobot2_description)/urdf/SomeRobot2.trans" />
<xacro:include filename="$(find SomeRobot2_description)/urdf/SomeRobot2.gazebo" />
<link name="base_link">
  <inertial>
    <origin rpy="0 0 0" xyz="0.003893173972092157 1.1666057995647583e-16 0.052918293473761084"/>
    <mass value="2.3138752403503786"/>
    <inertia ixx="0.007906" ixy="0.0" ixz="-0.000336" iyy="0.008403" iyz="-0.0" izz="0.014798"/>
  </inertial>
  <visual>
    <origin rpy="0 0 0" xyz="0 0 0"/>
    <geometry>
      <mesh filename="package://SomeRobot2_description/meshes/base_link.stl" scale="0.001 0.001 0.001"/>
    </geometry>
    <material name="silver"/>
  </visual>
  <collision>
    <origin rpy="0 0 0" xyz="0 0 0"/>
    <geometry>
      <mesh filename="package://SomeRobot2_description/meshes/base_link.stl" scale="0.001 0.001 0.001"/>
    </geometry>
  </collision>
</link>

<link name="right_wheel_1">
  <inertial>
    <origin rpy="0 0 0" xyz="-5.790023100122029e-18 -0.012499999999999997 0.0"/>
    <mass value="0.1826050729899067"/>
    <inertia ixx="0.000124" ixy="-0.0" ixz="0.0" iyy="0.000228" iyz="0.0" izz="0.000124"/>
  </inertial>
  <visual>
    <origin rpy="0 0 0" xyz="-0.0 0.1 -0.05"/>
    <geometry>
      <mesh filename="package://SomeRobot2_description/meshes/right_wheel_1.stl" scale="0.001 0.001 0.001"/>
    </geometry>
    <material name="silver"/>
  </visual>
  <collision>
    <origin rpy="0 0 0" xyz="-0.0 0.1 -0.05"/>
    <geometry>
      <mesh filename="package://SomeRobot2_description/meshes/right_wheel_1.stl" scale="0.001 0.001 0.001"/>
    </geometry>
  </collision>
</link>

<link name="left_wheel_1">
  <inertial>
    <origin rpy="0 0 0" xyz="-5.790023100122029e-18 0.012499999999999997 0.0"/>
    <mass value="0.1826050729899067"/>
    <inertia ixx="0.000124" ixy="0.0" ixz="0.0" iyy="0.000228" iyz="-0.0" izz="0.000124"/>
  </inertial>
  <visual>
    <origin rpy="0 0 0" xyz="-0.0 -0.1 -0.05"/>
    <geometry>
      <mesh filename="package://SomeRobot2_description/meshes/left_wheel_1.stl" scale="0.001 0.001 0.001"/>
    </geometry>
    <material name="silver"/>
  </visual>
  <collision>
    <origin rpy="0 0 0" xyz="-0.0 -0.1 -0.05"/>
    <geometry>
      <mesh filename="package://SomeRobot2_description/meshes/left_wheel_1.stl" scale="0.001 0.001 0.001"/>
    </geometry>
  </collision>
</link>

<link name="lidar_1">
  <inertial>
    <origin rpy="0 0 0" xyz="9.228728892196614e-16 2.87602420578978e-15 0.01250000000000133"/>
    <mass value="0.10789485809488787"/>
    <inertia ixx="4.1e-05" ixy="0.0" ixz="0.0" iyy="4.1e-05" iyz="0.0" izz="7e-05"/>
  </inertial>
  <visual>
    <origin rpy="0 0 0" xyz="-0.05 -0.0 -0.11"/>
    <geometry>
      <mesh filename="package://SomeRobot2_description/meshes/lidar_1.stl" scale="0.001 0.001 0.001"/>
    </geometry>
    <material name="silver"/>
  </visual>
  <collision>
    <origin rpy="0 0 0" xyz="-0.05 -0.0 -0.11"/>
    <geometry>
      <mesh filename="package://SomeRobot2_description/meshes/lidar_1.stl" scale="0.001 0.001 0.001"/>
    </geometry>
  </collision>
</link>

<joint name="Rev1" type="continuous">
  <origin rpy="0 0 0" xyz="0.0 -0.1 0.05"/>
  <parent link="base_link"/>
  <child link="right_wheel_1"/>
  <axis xyz="0.0 -1.0 0.0"/>
</joint>

<joint name="Rev2" type="continuous">
  <origin rpy="0 0 0" xyz="0.0 0.1 0.05"/>
  <parent link="base_link"/>
  <child link="left_wheel_1"/>
  <axis xyz="0.0 1.0 0.0"/>
</joint>

<joint name="Rigid3" type="fixed">
  <origin rpy="0 0 0" xyz="0.05 0.0 0.11"/>
  <parent link="base_link"/>
  <child link="lidar_1"/>
</joint>

</robot>
